Workbook

Sheet RESUMO
B2: DETALHAMENTO DO FATURAMENTO
B4: DISPONÍVEL PARA FATURAR | D4: FATURADO | E4: % DO FATURADO
B5: TOTAL GERAL | C5: =C7+C8+C9 -> 20 | D5: =SUMIF(SiteVisitP1[Data],">0",SiteVisitP1[Valor da Parcela])+SUMIF(Parcela1[Data],">0",Parcela1[Coluna1])+SUMIF(SiteVisitP110[NF],">0",SiteVisitP110[Valor da Parcela]) -> 0 | E5: =IF(D5=0,0,D5/C5) -> 0
B7: TOTAL - 7.02 | C7: =SUM(Parcela1[Coluna1]) -> 10 | D7: =SUM(SUMIF(Parcela1[NF],"<>"&"",Parcela1[Coluna1])) -> 0 | E7: =IF(D7=0,0,D7/C7) -> 0 | G7: =C7-D7 -> 10
B8: TOTAL - 7.03 | C8: =SUM(SiteVisitP1[Valor da Parcela]) -> 10 | D8: =SUMIF(SiteVisitP1[NF],">0",SiteVisitP1[Valor da Parcela]) -> 0 | E8: =IF(D8=0,0,D8/C8) -> 0
B9: TOTAL - 31.01 | C9: =SUM(SiteVisitP110[Valor da Parcela]) -> 0 | D9: =SUMIF(SiteVisitP110[NF],">0",SiteVisitP110[Valor da Parcela]) -> 0 | E9: =IF(D9=0,0,D9/C9) -> 0

Sheet PRIORIDADES
A3: Rótulos de Linha | B3: Soma de Total | C3: Contagem de UF
A4: BR_CE_FORTALEZA_Tax | B4: 4756.272 | C4: 12
A5: BR_PB_BOA VENTURA_Tax | B5: 4753.298 | C5: 9
A6: BR_CE_BREJO SANTO_Tax | B6: 4753.298 | C6: 9
A7: BR_SP_RIO DAS PEDRAS_Tax | B7: 4368.513 | C7: 6
A8: BR_RN_SANTA CRUZ_Tax | B8: 4062.816 | C8: 6
A9: BR_PE_RECIFE_Tax | B9: 3077.523 | C9: 5
A10: BR_SP_MAUA_Tax | B10: 3000 | C10: 1
A11: BR_CE_JUAZEIRO DO NORTE_Tax | B11: 2997.96 | C11: 8
A12: BR_SP_SANTA BARBARA D'OESTE_Tax | B12: 2846.178 | C12: 1
A13: BR_GO_ALTO PARAISO DE GOIAS_Tax | B13: 2815.344 | C13: 1
A14: BR_BA_VALENCA_Tax | B14: 2649.429 | C14: 1
A15: BR_BA_PIRAI DO NORTE_Tax | B15: 2649.429 | C15: 1
... A74: BR_GO_ORIZONA_Tax | B74: 39.022 | C74: 1
A75: (vazio)
A76: Total Geral | B76: 87951.994 | C76: 234

Sheet 7.03
C1: FATURAR POR PO | N1: =SUBTOTAL(9,SiteVisitP1[Valor da Parcela]) -> 10
A2: CC | B2: CÓDIGO FAT | C2: MUNICÍPIO | D2: UF | E2: SITE NAME | F2: OPERADORA | G2: PO | H2: LINE | I2: DU | J2: ItemCode | K2: Preço | L2: Qty | M2: Total | N2: Proporção | O2: Valor da Parcela | P2: NF | Q2: Data | U2: UF | V2: CC
A3: NE2 | B3: 7.03 | C3: BR_CE_AQUIRAZ_Tax | D3: CE | E3: CEAQU07 | F3: CLARO | G3: 6211HG3360340-1482 | H3: 1 | I3: 20250326476411 | J3: 8812441617 | K3: 10 | L3: 1,0000000000 | M3: 10 | N3: 1 | O3: 10
U135: MS | V135: CO
U136: TO | V136: CO
U137: RO | V137: CO
B251: MÁXIMO DE 25 LINHAS | I251: TOTAL DA NF | K251: =SUBTOTAL(9,M3:M249) -> 10
B253: PO | C253: LINE | D253: ="PO "&B253&" LINE "&C253&" " -> PO PO LINE LINE | I253: PIS 0,65% | J253: 0.0065 | K253: =ROUND(J253*K251,2) -> 0.07 | M253: IRRF 1,5% | N253: 0.015 | O253: =ROUND(N253*K251,2) -> 0.15
I254: COFINS 3% | J254: 0.03 | K254: =ROUND(J254*K251,2) -> 0.3 | M254: CSLL 1% | N254: 0.01 | O254: =ROUND(N254*K251,2) -> 0.1
B256: 6211HG3360338-553 | C256: 2 | D256: ="PO "&B256&" LINE "&C256&" " -> PO 6211HG3360338-553 LINE 2 | I256: LÍQUIDO NF | K256: =K251-K253-K254-O253-O254 -> 9.38
B257: 6211HG3360338-418 | C257: 2 | D257: ="PO "&B257&" LINE "&C257&" " -> PO 6211HG3360338-418 LINE 2
B258: 6211HG3360338-435 | C258: 1 | D258: ="PO "&B258&" LINE "&C258&" " -> PO 6211HG3360338-435 LINE 1 | I258: Elaboração de projetos de obras de construção civil e elétrica, referente a adequação de infraestrutura, instalação e montagem de equipamentos de rede de telefonia celular, conforme pedidos de compra abaixo:
I259: =CONCATENATE("PO: ",D256,"/",E256,", ",D257,"/",E257,", ",D258,"/",E258,", ",D259,"/",E259,", ",D260,"/",E260,", ",D261,"/",E261,", ",D262,"/",E262,", ",D263,"/",E263,", ",D264,"/",E264,", ",D265,"/",E265,", ",D266,"/",E266,", ",D267,"/",E267,", ",D268,"/",E268,", ",D269,"/",E269,", ",D270,"/",E270,", ",D271,"/",E271,", ",D272,"/",E272,", ",D273,"/",E273,", ",D274,"/",E274,", ",D275,"/",E275,", ",D276,"/",E276,", ",D277,"/",E277,", ",D278,"/",E278,", ",D279,"/",E279,", ",D280,"/",E280,", ",D281,"/",E281,", ",D282,"/",E282,", ",D283,"/",E283,", ",D284,"/",E284,", ",D285,"/",E285,", ",D286,"/",E286,", ",D287,"/",E287,", ",D288,"/",E288,", ",D289,"/",E289,", ",D290,"/",E290,", ",D291,"/",E291,", ",D292,"/",E292,", ",D293,"/",E293,", ",D294,"/",E294,", ",D295,"/",E295,", ",D296,"/",E296,", ",D297,"/",E297,", ",D298,"/",E298,", ",D299,"/",E299,", ",D300,"/",E300,", ",D301,"/",E301,", ",D302,"/",E302,", ",D303,"/",E303,", ",D304,"/",E304,", ",D305,"/",E305,", ",D306,"/",E306,", ",D307,"/",E307,", ",D308,"/",E308,", ",D309,"/",E309,", ",D310,"/",E310,", ",D311,"/",E311,", ",D312,"/",E312,", ",D313,"/",E313,", ",D314,"/",E314,", ",D315,"/",E315) -> PO: PO 6211HG3360338-553 LINE 2 /, PO 6211HG3360338-418 LINE 2 /, PO 6211HG3360338-435 LINE 1 /, /, /, /, /, /, /, /, /, /, /, /, /, /, /, /, /, /, /, /, /, /, /, /, /, /, /, /, /, /, /, /, /, /, /, /, /, /, /, /, /, /, /, /, /, /, /, /, /, /, /, /, /, /, /, /, /, /
I261: =CONCATENATE("Retenções: ",I253," ","R$ ",K253," ",I254," ","R$ ",K254," ",M253," ","R$ ",O253," ",M254," ","R$ ",O254) -> Retenções: PIS 0,65% R$ 0,07 COFINS 3% R$ 0,3 IRRF 1,5% R$ 0,15 CSLL 1% R$ 0,1
G263: 10.519.123/0001-97

Sheet 31.01
C1: FATURAR POR PO | N1: =SUBTOTAL(9,SiteVisitP110[Valor da Parcela]) -> 0
A2: CC | B2: CÓDIGO FAT | C2: MUNICÍPIO | D2: UF | E2: SITE NAME | F2: OPERADORA | G2: PO | H2: LINE | I2: DU | J2: ItemCode | K2: Preço | L2: Qty | M2: Total | N2: Proporção | O2: Valor da Parcela | P2: NF | Q2: Data | U2: UF | V2: CC
U18: MS | V18: CO
U19: TO | V19: CO
U20: RO | V20: CO
B138: MÁXIMO DE 25 LINHAS | I138: TOTAL DA NF | K138: =SUBTOTAL(9,M3:M136) -> 0
B140: PO | C140: LINE | D140: ="PO "&B140&" LINE "&C140&" " -> PO PO LINE LINE | I140: PIS 0,65% | J140: 0.0065 | K140: =ROUND(J140*K138,2) -> 0 | M140: IRRF 1,5% | N140: 0.015 | O140: =ROUND(N140*K138,2) -> 0
I141: COFINS 3% | J141: 0.03 | K141: =ROUND(J141*K138,2) -> 0 | M141: CSLL 1% | N141: 0.01 | O141: =ROUND(N141*K138,2) -> 0
B143: 6211HG3453276-56 | C143: 1 | D143: ="PO "&B143&" LINE "&C143&" " -> PO 6211HG3453276-56 LINE 1 | I143: LÍQUIDO NF | K143: =K138-K140-K141-O140-O141 -> 0
I145: Serviço técnicos em telecomunicações, conforme pedidos de compra abaixo:
I146: =CONCATENATE("PO: ",D143,"/",E143,", ",D144,"/",E144,", ",D145,"/",E145,", ",D146,"/",E146,", ",D147,"/",E147,", ",D148,"/",E148,", ",D149,"/",E149,", ",D150,"/",E150,", ",D151,"/",E151,", ",D152,"/",E152,", ",D153,"/",E153,", ",D154,"/",E154,", ",D155,"/",E155,", ",D156,"/",E156,", ",D157,"/",E157,", ",D158,"/",E158,", ",D159,"/",E159,", ",D160,"/",E160,", ",D161,"/",E161,", ",D162,"/",E162,", ",D163,"/",E163,", ",D164,"/",E164,", ",D165,"/",E165,", ",D166,"/",E166,", ",D167,"/",E167,", ",D168,"/",E168,", ",D169,"/",E169,", ",D170,"/",E170,", ",D171,"/",E171,", ",D172,"/",E172,", ",D173,"/",E173,", ",D174,"/",E174,", ",D175,"/",E175,", ",D176,"/",E176,", ",D177,"/",E177,", ",D178,"/",E178,", ",D179,"/",E179,", ",D180,"/",E180,", ",D181,"/",E181,", ",D182,"/",E182,", ",D183,"/",E183,", ",D184,"/",E184,", ",D185,"/",E185,", ",D186,"/",E186,", ",D187,"/",E187,", ",D188,"/",E188,", ",D189,"/",E189,", ",D190,"/",E190,", ",D191,"/",E191,", ",D192,"/",E192,", ",D193,"/",E193,", ",D194,"/",E194,", ",D195,"/",E195,", ",D196,"/",E196,", ",D197,"/",E197,", ",D198,"/",E198,", ",D199,"/",E199,", ",D200,"/",E200,", ",D201,"/",E201,", ",D202,"/",E202) -> PO: PO 6211HG3453276-56 LINE 1 /, /, /, /, /, /, /, /, /, /, /, /, /, /, /, /, /, /, /, /, /, /, /, /, /, /, /, /, /, /, /, /, /, /, /, /, /, /, /, /, /, /, /, /, /, /, /, /, /, /, /, /, /, /, /, /, /, /, /, /
I148: =CONCATENATE("Retenções: ",I140," ","R$ ",K140," ",I141," ","R$ ",K141," ",M140," ","R$ ",O140," ",M141," ","R$ ",O141) -> Retenções: PIS 0,65% R$ 0 COFINS 3% R$ 0 IRRF 1,5% R$ 0 CSLL 1% R$ 0
G150: 10.519.123/0001-97

Sheet 7.02 
C1: FATURAR POR MUNICÍPIO | N1: =SUBTOTAL(9,Parcela1[Coluna1]) -> 10
A2: SP TIM | B2: CÓDIGO FAT | C2: MUNICÍPIO | D2: UF | E2: SITE NAME | F2: OPERADORA | G2: PO | H2: LINE | I2: DU | J2: ItemCode | K2: Preço | L2: Qty | M2: Total | N2: Proporção | O2: Coluna1 | P2: NF | Q2: Data | S2: UF | T2: CC
A3: NE1 | B3: 7.02 | C3: BR_AL_MACEIO_Tax | D3: AL | E3: LOT_AL | F3: VIVO | G3: 6211HG3360340-3062 | H3: 5 | I3: 20250708589335 | J3: 8812441757 | K3: 10 | L3: 1,0000000000 | M3: 10 | N3: 1 | O3: 10
C1079: MÁXIMO DE 25 LINHAS | K1079: 7.02
K1080: TOTAL DA NF | M1080: =SUBTOTAL(9,O2:O1076) -> 10
C1081: PO | D1081: LINE | E1081: ="PO "&C1081&" LINE "&D1081&" " -> PO PO LINE LINE | H1081: MUNICÍPIO | I1081: UF
C1082: 6211HG3360340-2227 | D1082: 3 | E1082: ="PO "&C1082&" LINE "&D1082&" " -> PO 6211HG3360340-2227 LINE 3 | H1082: SANTA CRUZ | I1082: RN | K1082: DEDUÇÃO INSS | L1082: Sim
C1083: 6211HG3360340-2227 | D1083: 4 | E1083: ="PO "&C1083&" LINE "&D1083&" " -> PO 6211HG3360340-2227 LINE 4 | K1083: DEDUÇÃO ISS | L1083: 0 | M1083: COLOCAR PERCENTUAL
C1084: 6211HG3360340-2227 | D1084: 6 | E1084: ="PO "&C1084&" LINE "&D1084&" " -> PO 6211HG3360340-2227 LINE 6 | K1084: MATERIAL | L1084: =L1083 -> 0 | M1084: =IF(L1084=R1075,"0", ROUND(L1084*M1080,2)) -> 0
C1085: 6211HG3360340-2227 | D1085: 1 | E1085: ="PO "&C1085&" LINE "&D1085&" " -> PO 6211HG3360340-2227 LINE 1 | K1085: SERVIÇO | L1085: =IF(L1084="0%",100%,100%-L1084) -> 1 | M1085: =ROUND(L1085*M1080,2) -> 10 | P1085: NAJ
C1086: 6211HG3360340-2227 | D1086: 2 | E1086: ="PO "&C1086&" LINE "&D1086&" " -> PO 6211HG3360340-2227 LINE 2
C1087: 6211HG3360340-2227 | D1087: 5 | E1087: ="PO "&C1087&" LINE "&D1087&" " -> PO 6211HG3360340-2227 LINE 5 | K1087: BASE CALC. ISS | L1087: =IF(L1083="Não",100%,100%-L1083) -> 1 | M1087: =ROUND(L1087*M1080,2) -> 10
K1088: BASE CALC. INSS | L1088: 1 | M1088: =ROUND(L1088*M1080,2) -> 10
K1090: OUTRAS RETENÇÕES | L1090: 0.05 | M1090: =ROUND(L1090*M1087,2) -> 0.5
K1091: RET. INSS | L1091: 0.035 | M1091: =ROUND(L1091*M1088,2) -> 0.35
K1093: Líquido NF | M1093: =M1080-M1090-M1091 -> 9.15
H1095: 10.519.123/0001-97 | K1095: Execução por empreitada de obras de construção civil e elétrica – adequação de infraestrutura, instalação e montagem de equipamentos de rede de telefonia celular, conforme pedidos de compra abaixo:
K1096: =E1082&E1083&E1084&E1085&E1086&E1087&E1088&E1089&E1090&E1091&E1092&E1093&E1094&E1095&E1096&E1097&E1098&E1099&E1100&E1101&E1102&E1103&E1104&E1105&E1106&E1127 -> PO 6211HG3360340-2227 LINE 3 PO 6211HG3360340-2227 LINE 4 PO 6211HG3360340-2227 LINE 6 PO 6211HG3360340-2227 LINE 1 PO 6211HG3360340-2227 LINE 2 PO 6211HG3360340-2227 LINE 5
K1097: =CONCATENATE("Município: "&H1082&" /"&I1082) -> Município: SANTA CRUZ /RN
K1098: =CONCATENATE("Material "&L1084*100&"% - R$ "&M1084&" "&"Serviço "&L1085*100&"% - R$ "&M1085) -> Material 0% - R$ 0 Serviço 100% - R$ 10
K1099: =CONCATENATE("Base de Cálculo ISS - R$ "&M1087&" "&"Base de Cálculo INSS - R$ "&M1088) -> Base de Cálculo ISS - R$ 10 Base de Cálculo INSS - R$ 10
K1100: =CONCATENATE("Retenções ISS "&L1090*100&"%"&" Município: "&H1082&" /"&I1082&" "&" Retenções INSS "&L1091*100&"% ") -> Retenções ISS 5% Município: SANTA CRUZ /RN Retenções INSS 3,5%
K1101: O ISS desta NFS-e será retido pelo tomador de serviço.
J1102: LEGISLAÇÃO | K1102: =IFERROR(IF(H1082="","",VLOOKUP(H1082&" / "&I1082,#REF!,2,FALSE)),"")

Sheet BASE
K1: DIFERENÇA | L1: =M1-RESUMO!C5 -> 1259.028 | M1: =SUM(Tabela6[Valor da Parcela]) -> 1279.028
A3: CC | B3: CÓDIGO FAT | C3: MUNICÍPIO | D3: UF | E3: SITE NAME | F3: OPERADORA | G3: PO | H3: LINE | I3: DU | J3: ItemCode | K3: Preço | L3: Qty | M3: Total | N3: Proporção | O3: Valor da Parcela
A4: =IF(VLOOKUP(Tabela6[[#This Row],[UF]],'BASE CC'!B:C,2,0)="SP",IF(Tabela6[[#This Row],[OPERADORA]]="TIM","SP TIM","SPI"),VLOOKUP(Tabela6[[#This Row],[UF]],'BASE CC'!B:C,2,0)) -> NE2 | B4: =VLOOKUP(Tabela_Base_Financeiro[[#This Row],[Item code]],'COD.FAT'!B:C,2,0) -> 7.03 | C4: =Tabela_Base_Financeiro[[#This Row],[PO Ship TO]] -> BR_CE_AQUIRAZ_Tax | D4: =RIGHT(Tabela_Base_Financeiro[[#This Row],[Manufacturer]],2) -> CE | E4: =IF(VLOOKUP(Tabela_Base_Financeiro[[#This Row],[Project Code]],'COD. PROJETOS'!B:D,3,0)="VIVO",MID(Tabela_Base_Financeiro[[#This Row],[Manufacturer]],36,6),IF(VLOOKUP(Tabela_Base_Financeiro[[#This Row],[Project Code]],'COD. PROJETOS'!B:D,3,0)="CLARO",MID(Tabela_Base_Financeiro[[#This Row],[Manufacturer]],36,7),IF(VLOOKUP(Tabela_Base_Financeiro[[#This Row],[Project Code]],'COD. PROJETOS'!B:D,3,0)="TIM",MID(Tabela_Base_Financeiro[[#This Row],[Manufacturer]],36,9),"PROJETO?"))) -> CEAQU07 | F4: =VLOOKUP(Tabela_Base_Financeiro[[#This Row],[Project Code]],'COD. PROJETOS'!B:D,3,0) -> CLARO | G4: =IFERROR(Tabela_Base_Financeiro[[#This Row],[PO No,]],0) -> 6211HG3360340-1482 | H4: =IFERROR(Tabela_Base_Financeiro[[#This Row],[Line No,]],0) -> 1 | I4: =IFERROR(MID(Tabela_Base_Financeiro[[#This Row],[Manufacturer]],19,14),"") -> 20250326476411 | J4: =IFERROR(Tabela_Base_Financeiro[[#This Row],[Item code]],0) -> 8812441617 | K4: =IFERROR(Tabela_Base_Financeiro[[#This Row],[Unit Price]],0) -> 1240,5 | L4: =IFERROR(Tabela_Base_Financeiro[[#This Row],[AC Qty,]],0) -> 1,0000000000 | M4: =Tabela6[[#This Row],[Qty]]*Tabela6[[#This Row],[Preço]] -> 1240.5 | N4: =IFERROR(Tabela_Base_Financeiro[[#This Row],[Proportion]],0) -> 1 | O4: =Tabela6[[#This Row],[Proporção]]*Tabela6[[#This Row],[Total]] -> 1240.5
A5: =IF(VLOOKUP(Tabela6[[#This Row],[UF]],'BASE CC'!B:C,2,0)="SP",IF(Tabela6[[#This Row],[OPERADORA]]="TIM","SP TIM","SPI"),VLOOKUP(Tabela6[[#This Row],[UF]],'BASE CC'!B:C,2,0)) -> NE1 | B5: =VLOOKUP(Tabela_Base_Financeiro[[#This Row],[Item code]],'COD.FAT'!B:C,2,0) -> 7.02 | C5: =Tabela_Base_Financeiro[[#This Row],[PO Ship TO]] -> BR_AL_MACEIO_Tax | D5: =RIGHT(Tabela_Base_Financeiro[[#This Row],[Manufacturer]],2) -> AL | E5: =IF(VLOOKUP(Tabela_Base_Financeiro[[#This Row],[Project Code]],'COD. PROJETOS'!B:D,3,0)="VIVO",MID(Tabela_Base_Financeiro[[#This Row],[Manufacturer]],36,6),IF(VLOOKUP(Tabela_Base_Financeiro[[#This Row],[Project Code]],'COD. PROJETOS'!B:D,3,0)="CLARO",MID(Tabela_Base_Financeiro[[#This Row],[Manufacturer]],36,7),IF(VLOOKUP(Tabela_Base_Financeiro[[#This Row],[Project Code]],'COD. PROJETOS'!B:D,3,0)="TIM",MID(Tabela_Base_Financeiro[[#This Row],[Manufacturer]],36,9),"PROJETO?"))) -> LOT_AL | F5: =VLOOKUP(Tabela_Base_Financeiro[[#This Row],[Project Code]],'COD. PROJETOS'!B:D,3,0) -> VIVO | G5: =IFERROR(Tabela_Base_Financeiro[[#This Row],[PO No,]],0) -> 6211HG3360340-3062 | H5: =IFERROR(Tabela_Base_Financeiro[[#This Row],[Line No,]],0) -> 5 | I5: =IFERROR(MID(Tabela_Base_Financeiro[[#This Row],[Manufacturer]],19,14),"") -> 20250708589335 | J5: =IFERROR(Tabela_Base_Financeiro[[#This Row],[Item code]],0) -> 8812441757 | K5: =IFERROR(Tabela_Base_Financeiro[[#This Row],[Unit Price]],0) -> 38,528 | L5: =IFERROR(Tabela_Base_Financeiro[[#This Row],[AC Qty,]],0) -> 1,0000000000 | M5: =Tabela6[[#This Row],[Qty]]*Tabela6[[#This Row],[Preço]] -> 38.528 | N5: =IFERROR(Tabela_Base_Financeiro[[#This Row],[Proportion]],0) -> 1 | O5: =Tabela6[[#This Row],[Proporção]]*Tabela6[[#This Row],[Total]] -> 38.528
A6: =IF(VLOOKUP(Tabela6[[#This Row],[UF]],'BASE CC'!B:C,2,0)="SP",IF(Tabela6[[#This Row],[OPERADORA]]="TIM","SP TIM","SPI"),VLOOKUP(Tabela6[[#This Row],[UF]],'BASE CC'!B:C,2,0)) -> #N/A | B6: =VLOOKUP(Tabela_Base_Financeiro[[#This Row],[Item code]],'COD.FAT'!B:C,2,0) -> #N/A | C6: =Tabela_Base_Financeiro[[#This Row],[PO Ship TO]] -> 0 | D6: =RIGHT(Tabela_Base_Financeiro[[#This Row],[Manufacturer]],2) | E6: =IF(VLOOKUP(Tabela_Base_Financeiro[[#This Row],[Project Code]],'COD. PROJETOS'!B:D,3,0)="VIVO",MID(Tabela_Base_Financeiro[[#This Row],[Manufacturer]],36,6),IF(VLOOKUP(Tabela_Base_Financeiro[[#This Row],[Project Code]],'COD. PROJETOS'!B:D,3,0)="CLARO",MID(Tabela_Base_Financeiro[[#This Row],[Manufacturer]],36,7),IF(VLOOKUP(Tabela_Base_Financeiro[[#This Row],[Project Code]],'COD. PROJETOS'!B:D,3,0)="TIM",MID(Tabela_Base_Financeiro[[#This Row],[Manufacturer]],36,9),"PROJETO?"))) -> #N/A | F6: =VLOOKUP(Tabela_Base_Financeiro[[#This Row],[Project Code]],'COD. PROJETOS'!B:D,3,0) -> #N/A | G6: =IFERROR(Tabela_Base_Financeiro[[#This Row],[PO No,]],0) -> 0 | H6: =IFERROR(Tabela_Base_Financeiro[[#This Row],[Line No,]],0) -> 0 | I6: =IFERROR(MID(Tabela_Base_Financeiro[[#This Row],[Manufacturer]],19,14),"") | J6: =IFERROR(Tabela_Base_Financeiro[[#This Row],[Item code]],0) -> 0 | K6: =IFERROR(Tabela_Base_Financeiro[[#This Row],[Unit Price]],0) -> 0 | L6: =IFERROR(Tabela_Base_Financeiro[[#This Row],[AC Qty,]],0) -> 0 | M6: =Tabela6[[#This Row],[Qty]]*Tabela6[[#This Row],[Preço]] -> 0 | N6: =IFERROR(Tabela_Base_Financeiro[[#This Row],[Proportion]],0) -> 0 | O6: =Tabela6[[#This Row],[Proporção]]*Tabela6[[#This Row],[Total]] -> 0
A7: =IF(VLOOKUP(Tabela6[[#This Row],[UF]],'BASE CC'!B:C,2,0)="SP",IF(Tabela6[[#This Row],[OPERADORA]]="TIM","SP TIM","SPI"),VLOOKUP(Tabela6[[#This Row],[UF]],'BASE CC'!B:C,2,0)) -> #N/A | B7: =VLOOKUP(Tabela_Base_Financeiro[[#This Row],[Item code]],'COD.FAT'!B:C,2,0) -> #N/A | C7: =Tabela_Base_Financeiro[[#This Row],[PO Ship TO]] -> 0 | D7: =RIGHT(Tabela_Base_Financeiro[[#This Row],[Manufacturer]],2) | E7: =IF(VLOOKUP(Tabela_Base_Financeiro[[#This Row],[Project Code]],'COD. PROJETOS'!B:D,3,0)="VIVO",MID(Tabela_Base_Financeiro[[#This Row],[Manufacturer]],36,6),IF(VLOOKUP(Tabela_Base_Financeiro[[#This Row],[Project Code]],'COD. PROJETOS'!B:D,3,0)="CLARO",MID(Tabela_Base_Financeiro[[#This Row],[Manufacturer]],36,7),IF(VLOOKUP(Tabela_Base_Financeiro[[#This Row],[Project Code]],'COD. PROJETOS'!B:D,3,0)="TIM",MID(Tabela_Base_Financeiro[[#This Row],[Manufacturer]],36,9),"PROJETO?"))) -> #N/A | F7: =VLOOKUP(Tabela_Base_Financeiro[[#This Row],[Project Code]],'COD. PROJETOS'!B:D,3,0) -> #N/A | G7: =IFERROR(Tabela_Base_Financeiro[[#This Row],[PO No,]],0) -> 0 | H7: =IFERROR(Tabela_Base_Financeiro[[#This Row],[Line No,]],0) -> 0 | I7: =IFERROR(MID(Tabela_Base_Financeiro[[#This Row],[Manufacturer]],19,14),"") | J7: =IFERROR(Tabela_Base_Financeiro[[#This Row],[Item code]],0) -> 0 | K7: =IFERROR(Tabela_Base_Financeiro[[#This Row],[Unit Price]],0) -> 0 | L7: =IFERROR(Tabela_Base_Financeiro[[#This Row],[AC Qty,]],0) -> 0 | M7: =Tabela6[[#This Row],[Qty]]*Tabela6[[#This Row],[Preço]] -> 0 | N7: =IFERROR(Tabela_Base_Financeiro[[#This Row],[Proportion]],0) -> 0 | O7: =Tabela6[[#This Row],[Proporção]]*Tabela6[[#This Row],[Total]] -> 0
A8: =IF(VLOOKUP(Tabela6[[#This Row],[UF]],'BASE CC'!B:C,2,0)="SP",IF(Tabela6[[#This Row],[OPERADORA]]="TIM","SP TIM","SPI"),VLOOKUP(Tabela6[[#This Row],[UF]],'BASE CC'!B:C,2,0)) -> #N/A | B8: =VLOOKUP(Tabela_Base_Financeiro[[#This Row],[Item code]],'COD.FAT'!B:C,2,0) -> #N/A | C8: =Tabela_Base_Financeiro[[#This Row],[PO Ship TO]] -> 0 | D8: =RIGHT(Tabela_Base_Financeiro[[#This Row],[Manufacturer]],2) | E8: =IF(VLOOKUP(Tabela_Base_Financeiro[[#This Row],[Project Code]],'COD. PROJETOS'!B:D,3,0)="VIVO",MID(Tabela_Base_Financeiro[[#This Row],[Manufacturer]],36,6),IF(VLOOKUP(Tabela_Base_Financeiro[[#This Row],[Project Code]],'COD. PROJETOS'!B:D,3,0)="CLARO",MID(Tabela_Base_Financeiro[[#This Row],[Manufacturer]],36,7),IF(VLOOKUP(Tabela_Base_Financeiro[[#This Row],[Project Code]],'COD. PROJETOS'!B:D,3,0)="TIM",MID(Tabela_Base_Financeiro[[#This Row],[Manufacturer]],36,9),"PROJETO?"))) -> #N/A | F8: =VLOOKUP(Tabela_Base_Financeiro[[#This Row],[Project Code]],'COD. PROJETOS'!B:D,3,0) -> #N/A | G8: =IFERROR(Tabela_Base_Financeiro[[#This Row],[PO No,]],0) -> 0 | H8: =IFERROR(Tabela_Base_Financeiro[[#This Row],[Line No,]],0) -> 0 | I8: =IFERROR(MID(Tabela_Base_Financeiro[[#This Row],[Manufacturer]],19,14),"") | J8: =IFERROR(Tabela_Base_Financeiro[[#This Row],[Item code]],0) -> 0 | K8: =IFERROR(Tabela_Base_Financeiro[[#This Row],[Unit Price]],0) -> 0 | L8: =IFERROR(Tabela_Base_Financeiro[[#This Row],[AC Qty,]],0) -> 0 | M8: =Tabela6[[#This Row],[Qty]]*Tabela6[[#This Row],[Preço]] -> 0 | N8: =IFERROR(Tabela_Base_Financeiro[[#This Row],[Proportion]],0) -> 0 | O8: =Tabela6[[#This Row],[Proporção]]*Tabela6[[#This Row],[Total]] -> 0
A9: =IF(VLOOKUP(Tabela6[[#This Row],[UF]],'BASE CC'!B:C,2,0)="SP",IF(Tabela6[[#This Row],[OPERADORA]]="TIM","SP TIM","SPI"),VLOOKUP(Tabela6[[#This Row],[UF]],'BASE CC'!B:C,2,0)) -> #N/A | B9: =VLOOKUP(Tabela_Base_Financeiro[[#This Row],[Item code]],'COD.FAT'!B:C,2,0) -> #N/A | C9: =Tabela_Base_Financeiro[[#This Row],[PO Ship TO]] -> 0 | D9: =RIGHT(Tabela_Base_Financeiro[[#This Row],[Manufacturer]],2) | E9: =IF(VLOOKUP(Tabela_Base_Financeiro[[#This Row],[Project Code]],'COD. PROJETOS'!B:D,3,0)="VIVO",MID(Tabela_Base_Financeiro[[#This Row],[Manufacturer]],36,6),IF(VLOOKUP(Tabela_Base_Financeiro[[#This Row],[Project Code]],'COD. PROJETOS'!B:D,3,0)="CLARO",MID(Tabela_Base_Financeiro[[#This Row],[Manufacturer]],36,7),IF(VLOOKUP(Tabela_Base_Financeiro[[#This Row],[Project Code]],'COD. PROJETOS'!B:D,3,0)="TIM",MID(Tabela_Base_Financeiro[[#This Row],[Manufacturer]],36,9),"PROJETO?"))) -> #N/A | F9: =VLOOKUP(Tabela_Base_Financeiro[[#This Row],[Project Code]],'COD. PROJETOS'!B:D,3,0) -> #N/A | G9: =IFERROR(Tabela_Base_Financeiro[[#This Row],[PO No,]],0) -> 0 | H9: =IFERROR(Tabela_Base_Financeiro[[#This Row],[Line No,]],0) -> 0 | I9: =IFERROR(MID(Tabela_Base_Financeiro[[#This Row],[Manufacturer]],19,14),"") | J9: =IFERROR(Tabela_Base_Financeiro[[#This Row],[Item code]],0) -> 0 | K9: =IFERROR(Tabela_Base_Financeiro[[#This Row],[Unit Price]],0) -> 0 | L9: =IFERROR(Tabela_Base_Financeiro[[#This Row],[AC Qty,]],0) -> 0 | M9: =Tabela6[[#This Row],[Qty]]*Tabela6[[#This Row],[Preço]] -> 0 | N9: =IFERROR(Tabela_Base_Financeiro[[#This Row],[Proportion]],0) -> 0 | O9: =Tabela6[[#This Row],[Proporção]]*Tabela6[[#This Row],[Total]] -> 0
A10: =IF(VLOOKUP(Tabela6[[#This Row],[UF]],'BASE CC'!B:C,2,0)="SP",IF(Tabela6[[#This Row],[OPERADORA]]="TIM","SP TIM","SPI"),VLOOKUP(Tabela6[[#This Row],[UF]],'BASE CC'!B:C,2,0)) -> #N/A | B10: =VLOOKUP(Tabela_Base_Financeiro[[#This Row],[Item code]],'COD.FAT'!B:C,2,0) -> #N/A | C10: =Tabela_Base_Financeiro[[#This Row],[PO Ship TO]] -> 0 | D10: =RIGHT(Tabela_Base_Financeiro[[#This Row],[Manufacturer]],2) | E10: =IF(VLOOKUP(Tabela_Base_Financeiro[[#This Row],[Project Code]],'COD. PROJETOS'!B:D,3,0)="VIVO",MID(Tabela_Base_Financeiro[[#This Row],[Manufacturer]],36,6),IF(VLOOKUP(Tabela_Base_Financeiro[[#This Row],[Project Code]],'COD. PROJETOS'!B:D,3,0)="CLARO",MID(Tabela_Base_Financeiro[[#This Row],[Manufacturer]],36,7),IF(VLOOKUP(Tabela_Base_Financeiro[[#This Row],[Project Code]],'COD. PROJETOS'!B:D,3,0)="TIM",MID(Tabela_Base_Financeiro[[#This Row],[Manufacturer]],36,9),"PROJETO?"))) -> #N/A | F10: =VLOOKUP(Tabela_Base_Financeiro[[#This Row],[Project Code]],'COD. PROJETOS'!B:D,3,0) -> #N/A | G10: =IFERROR(Tabela_Base_Financeiro[[#This Row],[PO No,]],0) -> 0 | H10: =IFERROR(Tabela_Base_Financeiro[[#This Row],[Line No,]],0) -> 0 | I10: =IFERROR(MID(Tabela_Base_Financeiro[[#This Row],[Manufacturer]],19,14),"") | J10: =IFERROR(Tabela_Base_Financeiro[[#This Row],[Item code]],0) -> 0 | K10: =IFERROR(Tabela_Base_Financeiro[[#This Row],[Unit Price]],0) -> 0 | L10: =IFERROR(Tabela_Base_Financeiro[[#This Row],[AC Qty,]],0) -> 0 | M10: =Tabela6[[#This Row],[Qty]]*Tabela6[[#This Row],[Preço]] -> 0 | N10: =IFERROR(Tabela_Base_Financeiro[[#This Row],[Proportion]],0) -> 0 | O10: =Tabela6[[#This Row],[Proporção]]*Tabela6[[#This Row],[Total]] -> 0
A11: =IF(VLOOKUP(Tabela6[[#This Row],[UF]],'BASE CC'!B:C,2,0)="SP",IF(Tabela6[[#This Row],[OPERADORA]]="TIM","SP TIM","SPI"),VLOOKUP(Tabela6[[#This Row],[UF]],'BASE CC'!B:C,2,0)) -> #N/A | B11: =VLOOKUP(Tabela_Base_Financeiro[[#This Row],[Item code]],'COD.FAT'!B:C,2,0) -> #N/A | C11: =Tabela_Base_Financeiro[[#This Row],[PO Ship TO]] -> 0 | D11: =RIGHT(Tabela_Base_Financeiro[[#This Row],[Manufacturer]],2) | E11: =IF(VLOOKUP(Tabela_Base_Financeiro[[#This Row],[Project Code]],'COD. PROJETOS'!B:D,3,0)="VIVO",MID(Tabela_Base_Financeiro[[#This Row],[Manufacturer]],36,6),IF(VLOOKUP(Tabela_Base_Financeiro[[#This Row],[Project Code]],'COD. PROJETOS'!B:D,3,0)="CLARO",MID(Tabela_Base_Financeiro[[#This Row],[Manufacturer]],36,7),IF(VLOOKUP(Tabela_Base_Financeiro[[#This Row],[Project Code]],'COD. PROJETOS'!B:D,3,0)="TIM",MID(Tabela_Base_Financeiro[[#This Row],[Manufacturer]],36,9),"PROJETO?"))) -> #N/A | F11: =VLOOKUP(Tabela_Base_Financeiro[[#This Row],[Project Code]],'COD. PROJETOS'!B:D,3,0) -> #N/A | G11: =IFERROR(Tabela_Base_Financeiro[[#This Row],[PO No,]],0) -> 0 | H11: =IFERROR(Tabela_Base_Financeiro[[#This Row],[Line No,]],0) -> 0 | I11: =IFERROR(MID(Tabela_Base_Financeiro[[#This Row],[Manufacturer]],19,14),"") | J11: =IFERROR(Tabela_Base_Financeiro[[#This Row],[Item code]],0) -> 0 | K11: =IFERROR(Tabela_Base_Financeiro[[#This Row],[Unit Price]],0) -> 0 | L11: =IFERROR(Tabela_Base_Financeiro[[#This Row],[AC Qty,]],0) -> 0 | M11: =Tabela6[[#This Row],[Qty]]*Tabela6[[#This Row],[Preço]] -> 0 | N11: =IFERROR(Tabela_Base_Financeiro[[#This Row],[Proportion]],0) -> 0 | O11: =Tabela6[[#This Row],[Proporção]]*Tabela6[[#This Row],[Total]] -> 0
A12: =IF(VLOOKUP(Tabela6[[#This Row],[UF]],'BASE CC'!B:C,2,0)="SP",IF(Tabela6[[#This Row],[OPERADORA]]="TIM","SP TIM","SPI"),VLOOKUP(Tabela6[[#This Row],[UF]],'BASE CC'!B:C,2,0)) -> #N/A | B12: =VLOOKUP(Tabela_Base_Financeiro[[#This Row],[Item code]],'COD.FAT'!B:C,2,0) -> #N/A | C12: =Tabela_Base_Financeiro[[#This Row],[PO Ship TO]] -> 0 | D12: =RIGHT(Tabela_Base_Financeiro[[#This Row],[Manufacturer]],2) | E12: =IF(VLOOKUP(Tabela_Base_Financeiro[[#This Row],[Project Code]],'COD. PROJETOS'!B:D,3,0)="VIVO",MID(Tabela_Base_Financeiro[[#This Row],[Manufacturer]],36,6),IF(VLOOKUP(Tabela_Base_Financeiro[[#This Row],[Project Code]],'COD. PROJETOS'!B:D,3,0)="CLARO",MID(Tabela_Base_Financeiro[[#This Row],[Manufacturer]],36,7),IF(VLOOKUP(Tabela_Base_Financeiro[[#This Row],[Project Code]],'COD. PROJETOS'!B:D,3,0)="TIM",MID(Tabela_Base_Financeiro[[#This Row],[Manufacturer]],36,9),"PROJETO?"))) -> #N/A | F12: =VLOOKUP(Tabela_Base_Financeiro[[#This Row],[Project Code]],'COD. PROJETOS'!B:D,3,0) -> #N/A | G12: =IFERROR(Tabela_Base_Financeiro[[#This Row],[PO No,]],0) -> 0 | H12: =IFERROR(Tabela_Base_Financeiro[[#This Row],[Line No,]],0) -> 0 | I12: =IFERROR(MID(Tabela_Base_Financeiro[[#This Row],[Manufacturer]],19,14),"") | J12: =IFERROR(Tabela_Base_Financeiro[[#This Row],[Item code]],0) -> 0 | K12: =IFERROR(Tabela_Base_Financeiro[[#This Row],[Unit Price]],0) -> 0 | L12: =IFERROR(Tabela_Base_Financeiro[[#This Row],[AC Qty,]],0) -> 0 | M12: =Tabela6[[#This Row],[Qty]]*Tabela6[[#This Row],[Preço]] -> 0 | N12: =IFERROR(Tabela_Base_Financeiro[[#This Row],[Proportion]],0) -> 0 | O12: =Tabela6[[#This Row],[Proporção]]*Tabela6[[#This Row],[Total]] -> 0
A13: =IF(VLOOKUP(Tabela6[[#This Row],[UF]],'BASE CC'!B:C,2,0)="SP",IF(Tabela6[[#This Row],[OPERADORA]]="TIM","SP TIM","SPI"),VLOOKUP(Tabela6[[#This Row],[UF]],'BASE CC'!B:C,2,0)) -> #N/A | B13: =VLOOKUP(Tabela_Base_Financeiro[[#This Row],[Item code]],'COD.FAT'!B:C,2,0) -> #N/A | C13: =Tabela_Base_Financeiro[[#This Row],[PO Ship TO]] -> 0 | D13: =RIGHT(Tabela_Base_Financeiro[[#This Row],[Manufacturer]],2) | E13: =IF(VLOOKUP(Tabela_Base_Financeiro[[#This Row],[Project Code]],'COD. PROJETOS'!B:D,3,0)="VIVO",MID(Tabela_Base_Financeiro[[#This Row],[Manufacturer]],36,6),IF(VLOOKUP(Tabela_Base_Financeiro[[#This Row],[Project Code]],'COD. PROJETOS'!B:D,3,0)="CLARO",MID(Tabela_Base_Financeiro[[#This Row],[Manufacturer]],36,7),IF(VLOOKUP(Tabela_Base_Financeiro[[#This Row],[Project Code]],'COD. PROJETOS'!B:D,3,0)="TIM",MID(Tabela_Base_Financeiro[[#This Row],[Manufacturer]],36,9),"PROJETO?"))) -> #N/A | F13: =VLOOKUP(Tabela_Base_Financeiro[[#This Row],[Project Code]],'COD. PROJETOS'!B:D,3,0) -> #N/A | G13: =IFERROR(Tabela_Base_Financeiro[[#This Row],[PO No,]],0) -> 0 | H13: =IFERROR(Tabela_Base_Financeiro[[#This Row],[Line No,]],0) -> 0 | I13: =IFERROR(MID(Tabela_Base_Financeiro[[#This Row],[Manufacturer]],19,14),"") | J13: =IFERROR(Tabela_Base_Financeiro[[#This Row],[Item code]],0) -> 0 | K13: =IFERROR(Tabela_Base_Financeiro[[#This Row],[Unit Price]],0) -> 0 | L13: =IFERROR(Tabela_Base_Financeiro[[#This Row],[AC Qty,]],0) -> 0 | M13: =Tabela6[[#This Row],[Qty]]*Tabela6[[#This Row],[Preço]] -> 0 | N13: =IFERROR(Tabela_Base_Financeiro[[#This Row],[Proportion]],0) -> 0 | O13: =Tabela6[[#This Row],[Proporção]]*Tabela6[[#This Row],[Total]] -> 0
A14: =IF(VLOOKUP(Tabela6[[#This Row],[UF]],'BASE CC'!B:C,2,0)="SP",IF(Tabela6[[#This Row],[OPERADORA]]="TIM","SP TIM","SPI"),VLOOKUP(Tabela6[[#This Row],[UF]],'BASE CC'!B:C,2,0)) -> #N/A | B14: =VLOOKUP(Tabela_Base_Financeiro[[#This Row],[Item code]],'COD.FAT'!B:C,2,0) -> #N/A | C14: =Tabela_Base_Financeiro[[#This Row],[PO Ship TO]] -> 0 | D14: =RIGHT(Tabela_Base_Financeiro[[#This Row],[Manufacturer]],2) | E14: =IF(VLOOKUP(Tabela_Base_Financeiro[[#This Row],[Project Code]],'COD. PROJETOS'!B:D,3,0)="VIVO",MID(Tabela_Base_Financeiro[[#This Row],[Manufacturer]],36,6),IF(VLOOKUP(Tabela_Base_Financeiro[[#This Row],[Project Code]],'COD. PROJETOS'!B:D,3,0)="CLARO",MID(Tabela_Base_Financeiro[[#This Row],[Manufacturer]],36,7),IF(VLOOKUP(Tabela_Base_Financeiro[[#This Row],[Project Code]],'COD. PROJETOS'!B:D,3,0)="TIM",MID(Tabela_Base_Financeiro[[#This Row],[Manufacturer]],36,9),"PROJETO?"))) -> #N/A | F14: =VLOOKUP(Tabela_Base_Financeiro[[#This Row],[Project Code]],'COD. PROJETOS'!B:D,3,0) -> #N/A | G14: =IFERROR(Tabela_Base_Financeiro[[#This Row],[PO No,]],0) -> 0 | H14: =IFERROR(Tabela_Base_Financeiro[[#This Row],[Line No,]],0) -> 0 | I14: =IFERROR(MID(Tabela_Base_Financeiro[[#This Row],[Manufacturer]],19,14),"") | J14: =IFERROR(Tabela_Base_Financeiro[[#This Row],[Item code]],0) -> 0 | K14: =IFERROR(Tabela_Base_Financeiro[[#This Row],[Unit Price]],0) -> 0 | L14: =IFERROR(Tabela_Base_Financeiro[[#This Row],[AC Qty,]],0) -> 0 | M14: =Tabela6[[#This Row],[Qty]]*Tabela6[[#This Row],[Preço]] -> 0 | N14: =IFERROR(Tabela_Base_Financeiro[[#This Row],[Proportion]],0) -> 0 | O14: =Tabela6[[#This Row],[Proporção]]*Tabela6[[#This Row],[Total]] -> 0
A15: =IF(VLOOKUP(Tabela6[[#This Row],[UF]],'BASE CC'!B:C,2,0)="SP",IF(Tabela6[[#This Row],[OPERADORA]]="TIM","SP TIM","SPI"),VLOOKUP(Tabela6[[#This Row],[UF]],'BASE CC'!B:C,2,0)) -> #N/A | B15: =VLOOKUP(Tabela_Base_Financeiro[[#This Row],[Item code]],'COD.FAT'!B:C,2,0) -> #N/A | C15: =Tabela_Base_Financeiro[[#This Row],[PO Ship TO]] -> 0 | D15: =RIGHT(Tabela_Base_Financeiro[[#This Row],[Manufacturer]],2) | E15: =IF(VLOOKUP(Tabela_Base_Financeiro[[#This Row],[Project Code]],'COD. PROJETOS'!B:D,3,0)="VIVO",MID(Tabela_Base_Financeiro[[#This Row],[Manufacturer]],36,6),IF(VLOOKUP(Tabela_Base_Financeiro[[#This Row],[Project Code]],'COD. PROJETOS'!B:D,3,0)="CLARO",MID(Tabela_Base_Financeiro[[#This Row],[Manufacturer]],36,7),IF(VLOOKUP(Tabela_Base_Financeiro[[#This Row],[Project Code]],'COD. PROJETOS'!B:D,3,0)="TIM",MID(Tabela_Base_Financeiro[[#This Row],[Manufacturer]],36,9),"PROJETO?"))) -> #N/A | F15: =VLOOKUP(Tabela_Base_Financeiro[[#This Row],[Project Code]],'COD. PROJETOS'!B:D,3,0) -> #N/A | G15: =IFERROR(Tabela_Base_Financeiro[[#This Row],[PO No,]],0) -> 0 | H15: =IFERROR(Tabela_Base_Financeiro[[#This Row],[Line No,]],0) -> 0 | I15: =IFERROR(MID(Tabela_Base_Financeiro[[#This Row],[Manufacturer]],19,14),"") | J15: =IFERROR(Tabela_Base_Financeiro[[#This Row],[Item code]],0) -> 0 | K15: =IFERROR(Tabela_Base_Financeiro[[#This Row],[Unit Price]],0) -> 0 | L15: =IFERROR(Tabela_Base_Financeiro[[#This Row],[AC Qty,]],0) -> 0 | M15: =Tabela6[[#This Row],[Qty]]*Tabela6[[#This Row],[Preço]] -> 0 | N15: =IFERROR(Tabela_Base_Financeiro[[#This Row],[Proportion]],0) -> 0 | O15: =Tabela6[[#This Row],[Proporção]]*Tabela6[[#This Row],[Total]] -> 0
... A1119: =IF(VLOOKUP(Tabela6[[#This Row],[UF]],'BASE CC'!B:C,2,0)="SP",IF(Tabela6[[#This Row],[OPERADORA]]="TIM","SP TIM","SPI"),VLOOKUP(Tabela6[[#This Row],[UF]],'BASE CC'!B:C,2,0)) -> #VALUE! | B1119: =VLOOKUP(Tabela_Base_Financeiro[[#This Row],[Item code]],'COD.FAT'!B:C,2,0) -> #VALUE! | C1119: =Tabela_Base_Financeiro[[#This Row],[PO Ship TO]] -> #VALUE! | D1119: =RIGHT(Tabela_Base_Financeiro[[#This Row],[Manufacturer]],2) -> #VALUE! | E1119: =IF(VLOOKUP(Tabela_Base_Financeiro[[#This Row],[Project Code]],'COD. PROJETOS'!B:D,3,0)="VIVO",MID(Tabela_Base_Financeiro[[#This Row],[Manufacturer]],36,6),IF(VLOOKUP(Tabela_Base_Financeiro[[#This Row],[Project Code]],'COD. PROJETOS'!B:D,3,0)="CLARO",MID(Tabela_Base_Financeiro[[#This Row],[Manufacturer]],36,7),IF(VLOOKUP(Tabela_Base_Financeiro[[#This Row],[Project Code]],'COD. PROJETOS'!B:D,3,0)="TIM",MID(Tabela_Base_Financeiro[[#This Row],[Manufacturer]],36,9),"PROJETO?"))) -> #VALUE! | F1119: =VLOOKUP(Tabela_Base_Financeiro[[#This Row],[Project Code]],'COD. PROJETOS'!B:D,3,0) -> #VALUE! | G1119: =IFERROR(Tabela_Base_Financeiro[[#This Row],[PO No,]],0) -> 0 | H1119: =IFERROR(Tabela_Base_Financeiro[[#This Row],[Line No,]],0) -> 0 | I1119: =IFERROR(MID(Tabela_Base_Financeiro[[#This Row],[Manufacturer]],19,14),"") | J1119: =IFERROR(Tabela_Base_Financeiro[[#This Row],[Item code]],0) -> 0 | K1119: =IFERROR(Tabela_Base_Financeiro[[#This Row],[Unit Price]],0) -> 0 | L1119: =IFERROR(Tabela_Base_Financeiro[[#This Row],[AC Qty,]],0) -> 0 | M1119: =Tabela6[[#This Row],[Qty]]*Tabela6[[#This Row],[Preço]] -> 0 | N1119: =IFERROR(Tabela_Base_Financeiro[[#This Row],[Proportion]],0) -> 0 | O1119: =Tabela6[[#This Row],[Proporção]]*Tabela6[[#This Row],[Total]] -> 0

Sheet BASE FINANCEIRO
X1: X | AK1: X | AL1: X | AW1: X | BB1: X | BC1: X | BH1: X | BI1: X | CM1: =SUM(Tabela_Base_Financeiro[TOTAL]) -> 0
A3: Customer | B3: poLineLocationId | C3: vendorCode | D3: vendorId | E3: Companycode | F3: poHeadId | G3: poReleaseId | H3: polineId | I3: vendorSiteId | J3: termsId | K3: milestoneId | L3: digestCode | M3: invOrgId | N3: attribute2 | O3: poSource | P3: Location | Q3: CNPJ | R3: PO No, | S3: Release No, | T3: Line No, | U3: Shipment No, | V3: PO Type | W3: PO Qty | X3: AC Qty, | Y3: Billed Qty | Z3: offsetQty | AA3: Unbilled Qty, | AB3: Currency | AC3: shipToLocationId | AD3: Coluna1 | AE3: Coluna2 | AF3: Coluna3 | AG3: Coluna4 | AH3: Coluna5 | AI3: Coluna6 | AJ3: Coluna7 | AK3: Unit Price | AL3: LC Code | AM3: ISS Tax Type | AN3: ISS Rate | AO3: INSS Base Rate | AP3: INSS Rate | AQ3: IRRF Rate | AR3: PCC Rate | AS3: Terms Date Rule | AT3: Terms | AU3: site | AV3: Acceptance Milestone | AW3: Proportion | AX3: Description | AY3: Payment Type | AZ3: payment terms | BA3: Payment Method | BB3: Item code | BC3: Project Code | BD3: Project Name | BE3: Sub Contract No, | BF3: Sales Contract No, | BG3: UOM | BH3: PO Ship TO | BI3: Manufacturer | BJ3: Billing* | BK3: Invoice Type(Brazil) | BL3: DOC_Fiscal | BM3: Series | BN3: Invoice No* | BO3: Invoice Date* | BP3: Invoice Amount (Incl, Tax)* | BQ3: Invoice Key | BR3: BR BarCode | BS3: ICMS type | BT3: ICMS Base | BU3: ICMS Amount | BV3: ICMS ST Base | BW3: ICMS ST Amount | BX3: IPI Base | BY3: IPI Amount | BZ3: ISS_City | CA3: ISS_State | CB3: ISS_Base | CC3: Service_Code | CD3: Iss_Type | CE3: INSS_Base | CF3: INSS_Tax | CG3: IR_Type | CH3: IR_Categ | CI3: IR_Base | CJ3: IR_Rate | CK3: AWT_Group | CL3: remark | CM3: TOTAL
A4: Huawei Gestao e Servicos de Telecomunicacoes do Brasil Ltda, | B4: 1694297958383198214 | C4: AZ0149 | D4: 319275 | E4: 6211 | F4: 1694297958383198210 | H4: 1694297958383198212 | I4: 1701733 | J4: 500001 | L4: 240c4b46725f733536c9d490f21514ff35dbe39ae238f4a75d24c22d4ecea5a6 | M4: BM1 | O4: SERVICE_PROCUREMENT | P4: BM1_Financial | Q4: 10519123000197 | R4: 6211HG3360340-1482 | T4: 1 | U4: 1 | V4: SERVICE_PROCUREMENT | W4: 1 | X4: 1,0000000000 | Y4: 0 | Z4: 0 | AA4: 1 | AB4: BRL | AC4: 3000000795 | AD4: N | AK4: 1240,5 | AL4: 7,03 ELABORACAO PROJETOS | AT4: Pay On Agreement | AU4: BRA | AV4: AC1 | AW4: 1 | AX4: Additional site visit of installation team because of Huawei problem, per site | AZ4: 【TT】▍AC1 (100,00%, INV AC -30D, Complete 100%) ▍ | BB4: 8812441617 | BC4: 56A0CP2 | BE4: FPAMULTBRA25032510450326B1 | BF4: 00A07725169320 | BG4: SITE | BH4: BR_CE_AQUIRAZ_Tax | BI4: 200043946543000<!>20250326476411<!>CEAQU07_KEY@CEAQU07_GNODEB_MAIN_00D0772592030U_CE | BJ4: 1
A5: Huawei Gestao e Servicos de Telecomunicacoes do Brasil Ltda, | B5: 1766381519796641950 | C5: AZ0149 | D5: 319275 | E5: 6211 | F5: 1766381519796641866 | H5: 1766381519796641940 | I5: 1701733 | J5: 500001 | L5: fec633c658778a76202922c8ceed956501bfba414362284cb352c2f5fc6c5831 | M5: BM1 | O5: SERVICE_PROCUREMENT | P5: BM1_Financial | Q5: 10519123000197 | R5: 6211HG3360340-3062 | T5: 5 | U5: 2 | V5: SERVICE_PROCUREMENT | W5: 1 | X5: 1,0000000000 | Y5: 0 | Z5: 0 | AA5: 1 | AB5: BRL | AC5: 3000000246 | AD5: N | AK5: 38,528 | AL5: 7,02 INSTALACAO | AT5: Pay On Agreement | AU5: BRA | AV5: AC2 | AW5: 1 | AX5: RRU/AAU Dismantling (1-3 RRUs/AAUs) | AZ5: 【TT】▍AC1 (90,00%, INV AC -30D, Complete 90%) / AC2 (10,00%, INV AC -30D, Complete 100%) ▍ | BB5: 8812441757 | BC5: 56A0M7N | BE5: FPAMULTBRA25032510450326B1 | BF5: 00A07725232125 | BG5: SITE | BH5: BR_AL_MACEIO_Tax | BI5: 200045902309000<!>20250708589335<!>LOT_AL584624_00D07925490423_AL | BJ5: 1
A1115: Total | BH1115: =SUBTOTAL(103,Tabela_Base_Financeiro[PO Ship TO]) -> 2 | CM1115: =SUBTOTAL(103,Tabela_Base_Financeiro[TOTAL]) -> 0

Sheet COD. PROJETOS
B3: Project Code | C3: PROJETO | D3: OPERADORA
B4: 56A0939 | C4: VIVO WL | D4: VIVO
B5: 56A0A2P | C5: VIVO MW | D5: VIVO
B6: 56A0GFT | C6: VIVO WL | D6: VIVO
B7: 56A0F8R | C7: VIVO JERI | D7: VIVO
B8: 56A0HN1 | C8: VIVO MW | D8: VIVO
B9: 56A0CCC | C9: TIM WL | D9: TIM
B10: 56A05CP | C10: TIM MW | D10: TIM
B11: 56A08Y1 | C11: TIM BATTERY | D11: TIM
B12: 56A0CP2 | C12: CLARO WL | D12: CLARO
B13: 56A0G11 | C13: CLARO BATTERY | D13: CLARO
B14: 56A0KFU | C14: TIM WL | D14: TIM
... B26: 56A0T27 | C26: TIM SWAP | D26: TIM

Sheet BASE MUNICÍPIO
B2: Colunas1 | C2: Colunas2 | D2: Colunas3
B3: 18NLTICP01 | C3: TIJUCAS | D3: SC
B4: 3SLAUTC01 | C4: ARAUCARIA | D4: PR
B5: 4GBABDA5857 | C5: SALVADOR | D5: BA
B6: 4G-SAIG06 | C6: SALVADOR | D6: BA
B7: 7NLFSCE02 | C7: FEIRA DE SANTANA | D7: BA
B8: AAG | C8: ALAGOA GRANDE | D8: PB
B9: AAJ | C9: FORTALEZA | D9: CE
B10: AAL | C10: ARACOIABA | D10: CE
B11: AAX | C11: ARAPIRACA | D11: AL
B12: ABI | C12: ABAIARA | D12: CE
B13: ABM | C13: JABOATÃO DOS GUARARAPES | D13: PE
... B324: BASDR_0092 | C324: SALVADOR | D324: BA
B325: BASDR_0092_LIT | D325: BA
B326: BASER04 | C326: SERRINHA | D326: BA
B327: BASMF03 | C327: SIMÕES FILHO | D327: BA
B328: BASMF05 | C328: SIMÕES FILHO | D328: BA
B329: BASMF09 | C329: SIMÕES FILHO | D329: BA
B330: BASMF18 | C330: SIMÕES FILHO | D330: BA
B331: BASMF22 | C331: SIMÕES FILHO | D331: BA
B332: BASMF23 | C332: SIMÕES FILHO | D332: BA
B333: BASNB01 | C333: SANTA BÁRBARA | D333: BA
B334: BASNT01 | C334: SANTANA | D334: BA
B335: BASTZ03 | C335: ARACI | D335: BA
B336: BASUY01 | C336: SANTA LUZIA | D336: BA
B337: BATAP01 | C337: TAPIRAMUTÁ | D337: BA
... B464: CECUC04 | C464: CAUCAIA | D464: CE
B465: CECUC06 | D465: CE
B466: CECUC07 | C466: CAUCAIA | D466: CE
B467: CECUC11 | C467: CAUCAIA | D467: CE
B468: CECUC14 | C468: CAUCAIA | D468: CE
B469: CECVL02 | D469: CE
B470: CECZW01 | D470: CE
B471: CEEDS07 | C471: FORTALEZA | D471: CE
B472: CEEDS25 | C472: FORTALEZA | D472: CE
B473: CEESB03 | C473: EUSÉBIO | D473: CE
B474: CEFLA90 | C474: FORTALEZA | D474: CE
B475: CEHZT02 | C475: HORIZONTE | D475: CE
B476: CEIGE04 | C476: ITAPAGÉ | D476: CE
B477: CEIRA90 | D477: CE
...

Sheet COD. FAT
A3: WL
A4: CODE | B4: TAX CODE
A6: 8812288263 | B6: 7.02
A7: 8812288264 | B7: 7.02
A8: 8812288265 | B8: 7.02
A9: 8812288266 | B9: 7.02
A10: 8812288267 | B10: 7.02
A11: 8812288268 | B11: 7.02
A12: 8812288269 | B12: 7.02
A13: 8812288270 | B13: 7.02
A14: 8812288271 | B14: 7.02
A15: 8812288272 | B15: 7.02
A17: 8812288273 | B17: 7.02
A18: 8812288274 | B18: 7.02
A19: 8812288275 | B19: 7.02
A20: 8812288276 | B20: 7.02
A21: 8812288277 | B21: 7.02
A22: 8812288278 | B22: 7.02
... A118: 8818188310 | B118: 7.02
A120: MW
A121: BOM CODE | B121: TAX CODE
A123: 8812288355 | B123: 7.02
A124: 8812288356 | B124: 7.02
A125: 8812288357 | B125: 7.02
A126: 8812288358 | B126: 7.02
A127: 8812288359 | B127: 7.02
A128: 8812288360 | B128: 7.02
A129: 8812288361 | B129: 7.02
A131: 8812288362 | B131: 7.02
A132: 8812288363 | B132: 7.02
A133: 8812288364 | B133: 7.02
A134: 8812288365 | B134: 7.02
A135: 8812288366 | B135: 7.02
... A184: 8812288401 | B184: 7.02
A186: CW
A187: CODE | B187: TAX CODE
A189: 8818188174 | B189: 7.02
A190: 8818188175 | B190: 7.02
A191: 8818188176 | B191: 7.02
A192: 8818188177 | B192: 7.02
...

Sheet MUNICIPIO
A2: SITE | B2: SITE2 | C2: PROJETO | D2: SITE_ID | E2: MUNICÍPIO | F2: UF | G2: ESCOPO | H2: CIDADE
A3: ='BASE FINANCEIRO'!#REF! -> #REF! | B3: =MID(A3,36,14) -> #REF! | C3: tim | D3: =IF(VLOOKUP('BASE FINANCEIRO'!#REF!,'COD. PROJETOS'!B:D,3,0)="VIVO",MID('BASE FINANCEIRO'!#REF!,36,3),IF(VLOOKUP('BASE FINANCEIRO'!#REF!,'COD. PROJETOS'!B:D,3,0),MID('BASE FINANCEIRO'!#REF!,36,7),IF(VLOOKUP('BASE FINANCEIRO'!#REF!,'COD. PROJETOS'!B:D,3,0),MID('BASE FINANCEIRO'!#REF!,36,9),"PROJETO?"))) -> #REF! | E3: =VLOOKUP(D3,'BASE MUNICÍPIO'!B1:C24719,2,0) -> #REF! | F3: =VLOOKUP(D3,'BASE MUNICÍPIO'!B1:D24719,3,0) -> #REF! | G3: =IF(Tabela4[[#This Row],[PROJETO]]="CLARO",LEFT(Tabela4[[#This Row],[SITE2]],2),IF(Tabela4[[#This Row],[PROJETO]]="VIVO",RIGHT(LEFT(Tabela4[[#This Row],[SITE2]],10),2),""))
A4: ='BASE FINANCEIRO'!BI4 -> 200043946543000<!>20250326476411<!>CEAQU07_KEY@CEAQU07_GNODEB_MAIN_00D0772592030U_CE | B4: =MID(A4,36,14) -> CEAQU07_KEY@CE | C4: VIVO | D4: =IF(VLOOKUP('BASE FINANCEIRO'!BC4,'COD. PROJETOS'!B:D,3,0)="VIVO",MID('BASE FINANCEIRO'!BI4,36,3),IF(VLOOKUP('BASE FINANCEIRO'!BC4,'COD. PROJETOS'!B:D,3,0),MID('BASE FINANCEIRO'!BI4,36,7),IF(VLOOKUP('BASE FINANCEIRO'!BC4,'COD. PROJETOS'!B:D,3,0),MID('BASE FINANCEIRO'!BI4,36,9),"PROJETO?"))) -> #VALUE! | E4: =VLOOKUP(D4,'BASE MUNICÍPIO'!B2:C24720,2,0) -> #VALUE! | F4: =VLOOKUP(D4,'BASE MUNICÍPIO'!B2:D24720,3,0) -> #VALUE! | G4: =IF(Tabela4[[#This Row],[PROJETO]]="CLARO",LEFT(Tabela4[[#This Row],[SITE2]],2),IF(Tabela4[[#This Row],[PROJETO]]="VIVO",RIGHT(LEFT(Tabela4[[#This Row],[SITE2]],10),2),"")) -> KE
A5: ='BASE FINANCEIRO'!BI46 -> 0 | B5: =MID(A5,36,14) | C5: VIVO | D5: =IF(VLOOKUP('BASE FINANCEIRO'!BC46,'COD. PROJETOS'!B:D,3,0)="VIVO",MID('BASE FINANCEIRO'!BI46,36,3),IF(VLOOKUP('BASE FINANCEIRO'!BC46,'COD. PROJETOS'!B:D,3,0),MID('BASE FINANCEIRO'!BI46,36,7),IF(VLOOKUP('BASE FINANCEIRO'!BC46,'COD. PROJETOS'!B:D,3,0),MID('BASE FINANCEIRO'!BI46,36,9),"PROJETO?"))) -> #N/A | E5: =VLOOKUP(D5,'BASE MUNICÍPIO'!B3:C24721,2,0) -> #N/A | F5: =VLOOKUP(D5,'BASE MUNICÍPIO'!B3:D24721,3,0) -> #N/A | G5: =IF(Tabela4[[#This Row],[PROJETO]]="CLARO",LEFT(Tabela4[[#This Row],[SITE2]],2),IF(Tabela4[[#This Row],[PROJETO]]="VIVO",RIGHT(LEFT(Tabela4[[#This Row],[SITE2]],10),2),""))
A6: ='BASE FINANCEIRO'!BI47 -> 0 | B6: =MID(A6,36,14) | C6: VIVO | D6: =IF(VLOOKUP('BASE FINANCEIRO'!BC47,'COD. PROJETOS'!B:D,3,0)="VIVO",MID('BASE FINANCEIRO'!BI47,36,3),IF(VLOOKUP('BASE FINANCEIRO'!BC47,'COD. PROJETOS'!B:D,3,0),MID('BASE FINANCEIRO'!BI47,36,7),IF(VLOOKUP('BASE FINANCEIRO'!BC47,'COD. PROJETOS'!B:D,3,0),MID('BASE FINANCEIRO'!BI47,36,9),"PROJETO?"))) -> #N/A | E6: =VLOOKUP(D6,'BASE MUNICÍPIO'!B3:C24722,2,0) -> #N/A | F6: =VLOOKUP(D6,'BASE MUNICÍPIO'!B3:D24722,3,0) -> #N/A | G6: =IF(Tabela4[[#This Row],[PROJETO]]="CLARO",LEFT(Tabela4[[#This Row],[SITE2]],2),IF(Tabela4[[#This Row],[PROJETO]]="VIVO",RIGHT(LEFT(Tabela4[[#This Row],[SITE2]],10),2),""))
A7: ='BASE FINANCEIRO'!BI48 -> 0 | B7: =MID(A7,36,14) | C7: VIVO | D7: =IF(VLOOKUP('BASE FINANCEIRO'!BC48,'COD. PROJETOS'!B:D,3,0)="VIVO",MID('BASE FINANCEIRO'!BI48,36,3),IF(VLOOKUP('BASE FINANCEIRO'!BC48,'COD. PROJETOS'!B:D,3,0),MID('BASE FINANCEIRO'!BI48,36,7),IF(VLOOKUP('BASE FINANCEIRO'!BC48,'COD. PROJETOS'!B:D,3,0),MID('BASE FINANCEIRO'!BI48,36,9),"PROJETO?"))) -> #N/A | E7: =VLOOKUP(D7,'BASE MUNICÍPIO'!B4:C24723,2,0) -> #N/A | F7: =VLOOKUP(D7,'BASE MUNICÍPIO'!B4:D24723,3,0) -> #N/A | G7: =IF(Tabela4[[#This Row],[PROJETO]]="CLARO",LEFT(Tabela4[[#This Row],[SITE2]],2),IF(Tabela4[[#This Row],[PROJETO]]="VIVO",RIGHT(LEFT(Tabela4[[#This Row],[SITE2]],10),2),""))
A8: ='BASE FINANCEIRO'!BI49 -> 0 | B8: =MID(A8,36,14) | C8: VIVO | D8: =IF(VLOOKUP('BASE FINANCEIRO'!BC49,'COD. PROJETOS'!B:D,3,0)="VIVO",MID('BASE FINANCEIRO'!BI49,36,3),IF(VLOOKUP('BASE FINANCEIRO'!BC49,'COD. PROJETOS'!B:D,3,0),MID('BASE FINANCEIRO'!BI49,36,7),IF(VLOOKUP('BASE FINANCEIRO'!BC49,'COD. PROJETOS'!B:D,3,0),MID('BASE FINANCEIRO'!BI49,36,9),"PROJETO?"))) -> #N/A | E8: =VLOOKUP(D8,'BASE MUNICÍPIO'!B5:C24724,2,0) -> #N/A | F8: =VLOOKUP(D8,'BASE MUNICÍPIO'!B5:D24724,3,0) -> #N/A | G8: =IF(Tabela4[[#This Row],[PROJETO]]="CLARO",LEFT(Tabela4[[#This Row],[SITE2]],2),IF(Tabela4[[#This Row],[PROJETO]]="VIVO",RIGHT(LEFT(Tabela4[[#This Row],[SITE2]],10),2),""))
A9: ='BASE FINANCEIRO'!BI50 -> 0 | B9: =MID(A9,36,14) | C9: CLARO | D9: =IF(VLOOKUP('BASE FINANCEIRO'!BC50,'COD. PROJETOS'!B:D,3,0)="VIVO",MID('BASE FINANCEIRO'!BI50,36,3),IF(VLOOKUP('BASE FINANCEIRO'!BC50,'COD. PROJETOS'!B:D,3,0),MID('BASE FINANCEIRO'!BI50,36,7),IF(VLOOKUP('BASE FINANCEIRO'!BC50,'COD. PROJETOS'!B:D,3,0),MID('BASE FINANCEIRO'!BI50,36,9),"PROJETO?"))) -> #N/A | E9: =VLOOKUP(D9,'BASE MUNICÍPIO'!B6:C24725,2,0) -> #N/A | F9: =VLOOKUP(D9,'BASE MUNICÍPIO'!B6:D24725,3,0) -> #N/A | G9: =IF(Tabela4[[#This Row],[PROJETO]]="CLARO",LEFT(Tabela4[[#This Row],[SITE2]],2),IF(Tabela4[[#This Row],[PROJETO]]="VIVO",RIGHT(LEFT(Tabela4[[#This Row],[SITE2]],10),2),""))
A10: ='BASE FINANCEIRO'!BI51 -> 0 | B10: =MID(A10,36,14) | C10: VIVO | D10: =IF(VLOOKUP('BASE FINANCEIRO'!BC51,'COD. PROJETOS'!B:D,3,0)="VIVO",MID('BASE FINANCEIRO'!BI51,36,3),IF(VLOOKUP('BASE FINANCEIRO'!BC51,'COD. PROJETOS'!B:D,3,0),MID('BASE FINANCEIRO'!BI51,36,7),IF(VLOOKUP('BASE FINANCEIRO'!BC51,'COD. PROJETOS'!B:D,3,0),MID('BASE FINANCEIRO'!BI51,36,9),"PROJETO?"))) -> #N/A | E10: =VLOOKUP(D10,'BASE MUNICÍPIO'!B7:C24726,2,0) -> #N/A | F10: =VLOOKUP(D10,'BASE MUNICÍPIO'!B7:D24726,3,0) -> #N/A | G10: =IF(Tabela4[[#This Row],[PROJETO]]="CLARO",LEFT(Tabela4[[#This Row],[SITE2]],2),IF(Tabela4[[#This Row],[PROJETO]]="VIVO",RIGHT(LEFT(Tabela4[[#This Row],[SITE2]],10),2),""))
A11: ='BASE FINANCEIRO'!BI52 -> 0 | B11: =MID(A11,36,14) | C11: VIVO | D11: =IF(VLOOKUP('BASE FINANCEIRO'!BC52,'COD. PROJETOS'!B:D,3,0)="VIVO",MID('BASE FINANCEIRO'!BI52,36,3),IF(VLOOKUP('BASE FINANCEIRO'!BC52,'COD. PROJETOS'!B:D,3,0),MID('BASE FINANCEIRO'!BI52,36,7),IF(VLOOKUP('BASE FINANCEIRO'!BC52,'COD. PROJETOS'!B:D,3,0),MID('BASE FINANCEIRO'!BI52,36,9),"PROJETO?"))) -> #N/A | E11: =VLOOKUP(D11,'BASE MUNICÍPIO'!B8:C24727,2,0) -> #N/A | F11: =VLOOKUP(D11,'BASE MUNICÍPIO'!B8:D24727,3,0) -> #N/A | G11: =IF(Tabela4[[#This Row],[PROJETO]]="CLARO",LEFT(Tabela4[[#This Row],[SITE2]],2),IF(Tabela4[[#This Row],[PROJETO]]="VIVO",RIGHT(LEFT(Tabela4[[#This Row],[SITE2]],10),2),""))
A12: ='BASE FINANCEIRO'!BI53 -> 0 | B12: =MID(A12,36,14) | C12: VIVO | D12: =IF(VLOOKUP('BASE FINANCEIRO'!BC53,'COD. PROJETOS'!B:D,3,0)="VIVO",MID('BASE FINANCEIRO'!BI53,36,3),IF(VLOOKUP('BASE FINANCEIRO'!BC53,'COD. PROJETOS'!B:D,3,0),MID('BASE FINANCEIRO'!BI53,36,7),IF(VLOOKUP('BASE FINANCEIRO'!BC53,'COD. PROJETOS'!B:D,3,0),MID('BASE FINANCEIRO'!BI53,36,9),"PROJETO?"))) -> #N/A | E12: =VLOOKUP(D12,'BASE MUNICÍPIO'!B9:C24728,2,0) -> #N/A | F12: =VLOOKUP(D12,'BASE MUNICÍPIO'!B9:D24728,3,0) -> #N/A | G12: =IF(Tabela4[[#This Row],[PROJETO]]="CLARO",LEFT(Tabela4[[#This Row],[SITE2]],2),IF(Tabela4[[#This Row],[PROJETO]]="VIVO",RIGHT(LEFT(Tabela4[[#This Row],[SITE2]],10),2),""))
A13: ='BASE FINANCEIRO'!BI54 -> 0 | B13: =MID(A13,36,14) | C13: VIVO | D13: =IF(VLOOKUP('BASE FINANCEIRO'!BC54,'COD. PROJETOS'!B:D,3,0)="VIVO",MID('BASE FINANCEIRO'!BI54,36,3),IF(VLOOKUP('BASE FINANCEIRO'!BC54,'COD. PROJETOS'!B:D,3,0),MID('BASE FINANCEIRO'!BI54,36,7),IF(VLOOKUP('BASE FINANCEIRO'!BC54,'COD. PROJETOS'!B:D,3,0),MID('BASE FINANCEIRO'!BI54,36,9),"PROJETO?"))) -> #N/A | E13: =VLOOKUP(D13,'BASE MUNICÍPIO'!B10:C24729,2,0) -> #N/A | F13: =VLOOKUP(D13,'BASE MUNICÍPIO'!B10:D24729,3,0) -> #N/A | G13: =IF(Tabela4[[#This Row],[PROJETO]]="CLARO",LEFT(Tabela4[[#This Row],[SITE2]],2),IF(Tabela4[[#This Row],[PROJETO]]="VIVO",RIGHT(LEFT(Tabela4[[#This Row],[SITE2]],10),2),""))
A14: ='BASE FINANCEIRO'!BI55 -> 0 | B14: =MID(A14,36,14) | C14: VIVO | D14: =IF(VLOOKUP('BASE FINANCEIRO'!BC55,'COD. PROJETOS'!B:D,3,0)="VIVO",MID('BASE FINANCEIRO'!BI55,36,3),IF(VLOOKUP('BASE FINANCEIRO'!BC55,'COD. PROJETOS'!B:D,3,0),MID('BASE FINANCEIRO'!BI55,36,7),IF(VLOOKUP('BASE FINANCEIRO'!BC55,'COD. PROJETOS'!B:D,3,0),MID('BASE FINANCEIRO'!BI55,36,9),"PROJETO?"))) -> #N/A | E14: =VLOOKUP(D14,'BASE MUNICÍPIO'!B11:C24730,2,0) -> #N/A | F14: =VLOOKUP(D14,'BASE MUNICÍPIO'!B11:D24730,3,0) -> #N/A | G14: =IF(Tabela4[[#This Row],[PROJETO]]="CLARO",LEFT(Tabela4[[#This Row],[SITE2]],2),IF(Tabela4[[#This Row],[PROJETO]]="VIVO",RIGHT(LEFT(Tabela4[[#This Row],[SITE2]],10),2),""))
A15: ='BASE FINANCEIRO'!BI56 -> 0 | B15: =MID(A15,36,14) | C15: VIVO | D15: =IF(VLOOKUP('BASE FINANCEIRO'!BC56,'COD. PROJETOS'!B:D,3,0)="VIVO",MID('BASE FINANCEIRO'!BI56,36,3),IF(VLOOKUP('BASE FINANCEIRO'!BC56,'COD. PROJETOS'!B:D,3,0),MID('BASE FINANCEIRO'!BI56,36,7),IF(VLOOKUP('BASE FINANCEIRO'!BC56,'COD. PROJETOS'!B:D,3,0),MID('BASE FINANCEIRO'!BI56,36,9),"PROJETO?"))) -> #N/A | E15: =VLOOKUP(D15,'BASE MUNICÍPIO'!B12:C24731,2,0) -> #N/A | F15: =VLOOKUP(D15,'BASE MUNICÍPIO'!B12:D24731,3,0) -> #N/A | G15: =IF(Tabela4[[#This Row],[PROJETO]]="CLARO",LEFT(Tabela4[[#This Row],[SITE2]],2),IF(Tabela4[[#This Row],[PROJETO]]="VIVO",RIGHT(LEFT(Tabela4[[#This Row],[SITE2]],10),2),""))
A16: ='BASE FINANCEIRO'!BI57 -> 0 | B16: =MID(A16,36,14) | C16: VIVO | D16: =IF(VLOOKUP('BASE FINANCEIRO'!BC57,'COD. PROJETOS'!B:D,3,0)="VIVO",MID('BASE FINANCEIRO'!BI57,36,3),IF(VLOOKUP('BASE FINANCEIRO'!BC57,'COD. PROJETOS'!B:D,3,0),MID('BASE FINANCEIRO'!BI57,36,7),IF(VLOOKUP('BASE FINANCEIRO'!BC57,'COD. PROJETOS'!B:D,3,0),MID('BASE FINANCEIRO'!BI57,36,9),"PROJETO?"))) -> #N/A | E16: =VLOOKUP(D16,'BASE MUNICÍPIO'!B13:C24732,2,0) -> #N/A | F16: =VLOOKUP(D16,'BASE MUNICÍPIO'!B13:D24732,3,0) -> #N/A | G16: =IF(Tabela4[[#This Row],[PROJETO]]="CLARO",LEFT(Tabela4[[#This Row],[SITE2]],2),IF(Tabela4[[#This Row],[PROJETO]]="VIVO",RIGHT(LEFT(Tabela4[[#This Row],[SITE2]],10),2),""))
A17: ='BASE FINANCEIRO'!BI58 -> 0 | B17: =MID(A17,36,14) | C17: VIVO | D17: =IF(VLOOKUP('BASE FINANCEIRO'!BC58,'COD. PROJETOS'!B:D,3,0)="VIVO",MID('BASE FINANCEIRO'!BI58,36,3),IF(VLOOKUP('BASE FINANCEIRO'!BC58,'COD. PROJETOS'!B:D,3,0),MID('BASE FINANCEIRO'!BI58,36,7),IF(VLOOKUP('BASE FINANCEIRO'!BC58,'COD. PROJETOS'!B:D,3,0),MID('BASE FINANCEIRO'!BI58,36,9),"PROJETO?"))) -> #N/A | E17: =VLOOKUP(D17,'BASE MUNICÍPIO'!B14:C24733,2,0) -> #N/A | F17: =VLOOKUP(D17,'BASE MUNICÍPIO'!B14:D24733,3,0) -> #N/A | G17: =IF(Tabela4[[#This Row],[PROJETO]]="CLARO",LEFT(Tabela4[[#This Row],[SITE2]],2),IF(Tabela4[[#This Row],[PROJETO]]="VIVO",RIGHT(LEFT(Tabela4[[#This Row],[SITE2]],10),2),""))
A18: ='BASE FINANCEIRO'!#REF! -> #REF! | B18: =MID(A18,36,14) -> #REF! | C18: VIVO | D18: =IF(VLOOKUP('BASE FINANCEIRO'!#REF!,'COD. PROJETOS'!B:D,3,0)="VIVO",MID('BASE FINANCEIRO'!#REF!,36,3),IF(VLOOKUP('BASE FINANCEIRO'!#REF!,'COD. PROJETOS'!B:D,3,0),MID('BASE FINANCEIRO'!#REF!,36,7),IF(VLOOKUP('BASE FINANCEIRO'!#REF!,'COD. PROJETOS'!B:D,3,0),MID('BASE FINANCEIRO'!#REF!,36,9),"PROJETO?"))) -> #REF! | E18: =VLOOKUP(D18,'BASE MUNICÍPIO'!B15:C24734,2,0) -> #REF! | F18: =VLOOKUP(D18,'BASE MUNICÍPIO'!B15:D24734,3,0) -> #REF! | G18: =IF(Tabela4[[#This Row],[PROJETO]]="CLARO",LEFT(Tabela4[[#This Row],[SITE2]],2),IF(Tabela4[[#This Row],[PROJETO]]="VIVO",RIGHT(LEFT(Tabela4[[#This Row],[SITE2]],10),2),"")) -> #REF!
A19: ='BASE FINANCEIRO'!BI59 -> 0 | B19: =MID(A19,36,14) | C19: VIVO | D19: =IF(VLOOKUP('BASE FINANCEIRO'!BC59,'COD. PROJETOS'!B:D,3,0)="VIVO",MID('BASE FINANCEIRO'!BI59,36,3),IF(VLOOKUP('BASE FINANCEIRO'!BC59,'COD. PROJETOS'!B:D,3,0),MID('BASE FINANCEIRO'!BI59,36,7),IF(VLOOKUP('BASE FINANCEIRO'!BC59,'COD. PROJETOS'!B:D,3,0),MID('BASE FINANCEIRO'!BI59,36,9),"PROJETO?"))) -> #N/A | E19: =VLOOKUP(D19,'BASE MUNICÍPIO'!B16:C24735,2,0) -> #N/A | F19: =VLOOKUP(D19,'BASE MUNICÍPIO'!B16:D24735,3,0) -> #N/A | G19: =IF(Tabela4[[#This Row],[PROJETO]]="CLARO",LEFT(Tabela4[[#This Row],[SITE2]],2),IF(Tabela4[[#This Row],[PROJETO]]="VIVO",RIGHT(LEFT(Tabela4[[#This Row],[SITE2]],10),2),""))
A20: ='BASE FINANCEIRO'!BI60 -> 0 | B20: =MID(A20,36,14) | C20: VIVO | D20: =IF(VLOOKUP('BASE FINANCEIRO'!BC60,'COD. PROJETOS'!B:D,3,0)="VIVO",MID('BASE FINANCEIRO'!BI60,36,3),IF(VLOOKUP('BASE FINANCEIRO'!BC60,'COD. PROJETOS'!B:D,3,0),MID('BASE FINANCEIRO'!BI60,36,7),IF(VLOOKUP('BASE FINANCEIRO'!BC60,'COD. PROJETOS'!B:D,3,0),MID('BASE FINANCEIRO'!BI60,36,9),"PROJETO?"))) -> #N/A | E20: =VLOOKUP(D20,'BASE MUNICÍPIO'!B17:C24736,2,0) -> #N/A | F20: =VLOOKUP(D20,'BASE MUNICÍPIO'!B17:D24736,3,0) -> #N/A | G20: =IF(Tabela4[[#This Row],[PROJETO]]="CLARO",LEFT(Tabela4[[#This Row],[SITE2]],2),IF(Tabela4[[#This Row],[PROJETO]]="VIVO",RIGHT(LEFT(Tabela4[[#This Row],[SITE2]],10),2),""))
A21: ='BASE FINANCEIRO'!BI61 -> 0 | B21: =MID(A21,36,14) | C21: VIVO | D21: =IF(VLOOKUP('BASE FINANCEIRO'!BC61,'COD. PROJETOS'!B:D,3,0)="VIVO",MID('BASE FINANCEIRO'!BI61,36,3),IF(VLOOKUP('BASE FINANCEIRO'!BC61,'COD. PROJETOS'!B:D,3,0),MID('BASE FINANCEIRO'!BI61,36,7),IF(VLOOKUP('BASE FINANCEIRO'!BC61,'COD. PROJETOS'!B:D,3,0),MID('BASE FINANCEIRO'!BI61,36,9),"PROJETO?"))) -> #N/A | E21: =VLOOKUP(D21,'BASE MUNICÍPIO'!B18:C24737,2,0) -> #N/A | F21: =VLOOKUP(D21,'BASE MUNICÍPIO'!B18:D24737,3,0) -> #N/A | G21: =IF(Tabela4[[#This Row],[PROJETO]]="CLARO",LEFT(Tabela4[[#This Row],[SITE2]],2),IF(Tabela4[[#This Row],[PROJETO]]="VIVO",RIGHT(LEFT(Tabela4[[#This Row],[SITE2]],10),2),""))
A22: ='BASE FINANCEIRO'!BI62 -> 0 | B22: =MID(A22,36,14) | C22: VIVO | D22: =IF(VLOOKUP('BASE FINANCEIRO'!BC62,'COD. PROJETOS'!B:D,3,0)="VIVO",MID('BASE FINANCEIRO'!BI62,36,3),IF(VLOOKUP('BASE FINANCEIRO'!BC62,'COD. PROJETOS'!B:D,3,0),MID('BASE FINANCEIRO'!BI62,36,7),IF(VLOOKUP('BASE FINANCEIRO'!BC62,'COD. PROJETOS'!B:D,3,0),MID('BASE FINANCEIRO'!BI62,36,9),"PROJETO?"))) -> #N/A | E22: =VLOOKUP(D22,'BASE MUNICÍPIO'!B19:C24738,2,0) -> #N/A | F22: =VLOOKUP(D22,'BASE MUNICÍPIO'!B19:D24738,3,0) -> #N/A | G22: =IF(Tabela4[[#This Row],[PROJETO]]="CLARO",LEFT(Tabela4[[#This Row],[SITE2]],2),IF(Tabela4[[#This Row],[PROJETO]]="VIVO",RIGHT(LEFT(Tabela4[[#This Row],[SITE2]],10),2),""))
A23: ='BASE FINANCEIRO'!BI63 -> 0 | B23: =MID(A23,36,14) | C23: VIVO | D23: =IF(VLOOKUP('BASE FINANCEIRO'!BC63,'COD. PROJETOS'!B:D,3,0)="VIVO",MID('BASE FINANCEIRO'!BI63,36,3),IF(VLOOKUP('BASE FINANCEIRO'!BC63,'COD. PROJETOS'!B:D,3,0),MID('BASE FINANCEIRO'!BI63,36,7),IF(VLOOKUP('BASE FINANCEIRO'!BC63,'COD. PROJETOS'!B:D,3,0),MID('BASE FINANCEIRO'!BI63,36,9),"PROJETO?"))) -> #N/A | E23: =VLOOKUP(D23,'BASE MUNICÍPIO'!B20:C24739,2,0) -> #N/A | F23: =VLOOKUP(D23,'BASE MUNICÍPIO'!B20:D24739,3,0) -> #N/A | G23: =IF(Tabela4[[#This Row],[PROJETO]]="CLARO",LEFT(Tabela4[[#This Row],[SITE2]],2),IF(Tabela4[[#This Row],[PROJETO]]="VIVO",RIGHT(LEFT(Tabela4[[#This Row],[SITE2]],10),2),""))
A24: ='BASE FINANCEIRO'!BI64 -> 0 | B24: =MID(A24,36,14) | C24: VIVO | D24: =IF(VLOOKUP('BASE FINANCEIRO'!BC64,'COD. PROJETOS'!B:D,3,0)="VIVO",MID('BASE FINANCEIRO'!BI64,36,3),IF(VLOOKUP('BASE FINANCEIRO'!BC64,'COD. PROJETOS'!B:D,3,0),MID('BASE FINANCEIRO'!BI64,36,7),IF(VLOOKUP('BASE FINANCEIRO'!BC64,'COD. PROJETOS'!B:D,3,0),MID('BASE FINANCEIRO'!BI64,36,9),"PROJETO?"))) -> #N/A | E24: =VLOOKUP(D24,'BASE MUNICÍPIO'!B21:C24740,2,0) -> #N/A | F24: =VLOOKUP(D24,'BASE MUNICÍPIO'!B21:D24740,3,0) -> #N/A | G24: =IF(Tabela4[[#This Row],[PROJETO]]="CLARO",LEFT(Tabela4[[#This Row],[SITE2]],2),IF(Tabela4[[#This Row],[PROJETO]]="VIVO",RIGHT(LEFT(Tabela4[[#This Row],[SITE2]],10),2),""))
A25: ='BASE FINANCEIRO'!BI65 -> 0 | B25: =MID(A25,36,14) | C25: VIVO | D25: =IF(VLOOKUP('BASE FINANCEIRO'!BC65,'COD. PROJETOS'!B:D,3,0)="VIVO",MID('BASE FINANCEIRO'!BI65,36,3),IF(VLOOKUP('BASE FINANCEIRO'!BC65,'COD. PROJETOS'!B:D,3,0),MID('BASE FINANCEIRO'!BI65,36,7),IF(VLOOKUP('BASE FINANCEIRO'!BC65,'COD. PROJETOS'!B:D,3,0),MID('BASE FINANCEIRO'!BI65,36,9),"PROJETO?"))) -> #N/A | E25: =VLOOKUP(D25,'BASE MUNICÍPIO'!B22:C24741,2,0) -> #N/A | F25: =VLOOKUP(D25,'BASE MUNICÍPIO'!B22:D24741,3,0) -> #N/A | G25: =IF(Tabela4[[#This Row],[PROJETO]]="CLARO",LEFT(Tabela4[[#This Row],[SITE2]],2),IF(Tabela4[[#This Row],[PROJETO]]="VIVO",RIGHT(LEFT(Tabela4[[#This Row],[SITE2]],10),2),""))
A26: ='BASE FINANCEIRO'!BI66 -> 0 | B26: =MID(A26,36,14) | C26: VIVO | D26: =IF(VLOOKUP('BASE FINANCEIRO'!BC66,'COD. PROJETOS'!B:D,3,0)="VIVO",MID('BASE FINANCEIRO'!BI66,36,3),IF(VLOOKUP('BASE FINANCEIRO'!BC66,'COD. PROJETOS'!B:D,3,0),MID('BASE FINANCEIRO'!BI66,36,7),IF(VLOOKUP('BASE FINANCEIRO'!BC66,'COD. PROJETOS'!B:D,3,0),MID('BASE FINANCEIRO'!BI66,36,9),"PROJETO?"))) -> #N/A | E26: =VLOOKUP(D26,'BASE MUNICÍPIO'!B23:C24742,2,0) -> #N/A | F26: =VLOOKUP(D26,'BASE MUNICÍPIO'!B23:D24742,3,0) -> #N/A | G26: =IF(Tabela4[[#This Row],[PROJETO]]="CLARO",LEFT(Tabela4[[#This Row],[SITE2]],2),IF(Tabela4[[#This Row],[PROJETO]]="VIVO",RIGHT(LEFT(Tabela4[[#This Row],[SITE2]],10),2),""))
A27: ='BASE FINANCEIRO'!BI67 -> 0 | B27: =MID(A27,36,14) | C27: VIVO | D27: =IF(VLOOKUP('BASE FINANCEIRO'!BC67,'COD. PROJETOS'!B:D,3,0)="VIVO",MID('BASE FINANCEIRO'!BI67,36,3),IF(VLOOKUP('BASE FINANCEIRO'!BC67,'COD. PROJETOS'!B:D,3,0),MID('BASE FINANCEIRO'!BI67,36,7),IF(VLOOKUP('BASE FINANCEIRO'!BC67,'COD. PROJETOS'!B:D,3,0),MID('BASE FINANCEIRO'!BI67,36,9),"PROJETO?"))) -> #N/A | E27: =VLOOKUP(D27,'BASE MUNICÍPIO'!B23:C24743,2,0) -> #N/A | F27: =VLOOKUP(D27,'BASE MUNICÍPIO'!B23:D24743,3,0) -> #N/A | G27: =IF(Tabela4[[#This Row],[PROJETO]]="CLARO",LEFT(Tabela4[[#This Row],[SITE2]],2),IF(Tabela4[[#This Row],[PROJETO]]="VIVO",RIGHT(LEFT(Tabela4[[#This Row],[SITE2]],10),2),""))
A28: ='BASE FINANCEIRO'!BI68 -> 0 | B28: =MID(A28,36,14) | C28: VIVO | D28: =IF(VLOOKUP('BASE FINANCEIRO'!BC68,'COD. PROJETOS'!B:D,3,0)="VIVO",MID('BASE FINANCEIRO'!BI68,36,3),IF(VLOOKUP('BASE FINANCEIRO'!BC68,'COD. PROJETOS'!B:D,3,0),MID('BASE FINANCEIRO'!BI68,36,7),IF(VLOOKUP('BASE FINANCEIRO'!BC68,'COD. PROJETOS'!B:D,3,0),MID('BASE FINANCEIRO'!BI68,36,9),"PROJETO?"))) -> #N/A | E28: =VLOOKUP(D28,'BASE MUNICÍPIO'!B23:C24744,2,0) -> #N/A | F28: =VLOOKUP(D28,'BASE MUNICÍPIO'!B23:D24744,3,0) -> #N/A | G28: =IF(Tabela4[[#This Row],[PROJETO]]="CLARO",LEFT(Tabela4[[#This Row],[SITE2]],2),IF(Tabela4[[#This Row],[PROJETO]]="VIVO",RIGHT(LEFT(Tabela4[[#This Row],[SITE2]],10),2),""))
A29: ='BASE FINANCEIRO'!BI69 -> 0 | B29: =MID(A29,36,14) | C29: VIVO | D29: =IF(VLOOKUP('BASE FINANCEIRO'!BC69,'COD. PROJETOS'!B:D,3,0)="VIVO",MID('BASE FINANCEIRO'!BI69,36,3),IF(VLOOKUP('BASE FINANCEIRO'!BC69,'COD. PROJETOS'!B:D,3,0),MID('BASE FINANCEIRO'!BI69,36,7),IF(VLOOKUP('BASE FINANCEIRO'!BC69,'COD. PROJETOS'!B:D,3,0),MID('BASE FINANCEIRO'!BI69,36,9),"PROJETO?"))) -> #N/A | E29: =VLOOKUP(D29,'BASE MUNICÍPIO'!B24:C24745,2,0) -> #N/A | F29: =VLOOKUP(D29,'BASE MUNICÍPIO'!B24:D24745,3,0) -> #N/A | G29: =IF(Tabela4[[#This Row],[PROJETO]]="CLARO",LEFT(Tabela4[[#This Row],[SITE2]],2),IF(Tabela4[[#This Row],[PROJETO]]="VIVO",RIGHT(LEFT(Tabela4[[#This Row],[SITE2]],10),2),""))
A30: ='BASE FINANCEIRO'!BI70 -> 0 | B30: =MID(A30,36,14) | C30: VIVO | D30: =IF(VLOOKUP('BASE FINANCEIRO'!BC70,'COD. PROJETOS'!B:D,3,0)="VIVO",MID('BASE FINANCEIRO'!BI70,36,3),IF(VLOOKUP('BASE FINANCEIRO'!BC70,'COD. PROJETOS'!B:D,3,0),MID('BASE FINANCEIRO'!BI70,36,7),IF(VLOOKUP('BASE FINANCEIRO'!BC70,'COD. PROJETOS'!B:D,3,0),MID('BASE FINANCEIRO'!BI70,36,9),"PROJETO?"))) -> #N/A | E30: =VLOOKUP(D30,'BASE MUNICÍPIO'!B24:C24746,2,0) -> #N/A | F30: =VLOOKUP(D30,'BASE MUNICÍPIO'!B24:D24746,3,0) -> #N/A | G30: =IF(Tabela4[[#This Row],[PROJETO]]="CLARO",LEFT(Tabela4[[#This Row],[SITE2]],2),IF(Tabela4[[#This Row],[PROJETO]]="VIVO",RIGHT(LEFT(Tabela4[[#This Row],[SITE2]],10),2),""))
